<?xml version="1.0" ?>
<robot xmlns:xacro="http://ros.org/wiki/xacro">


  	<!-- Import all Gazebo-customization elements, including Gazebo colors -->
  	<xacro:include filename="$(find fabribot_description)/urdf/fabribot.gazebo" />

	<xacro:macro name="fabribot" params="prefix">


		<!-- Used for fixing robot to Gazebo 'base_link' -->
		<link name="${prefix}world"/>

		<!-- link list -->
		<link name="${prefix}base_link">
			<visual>
     			<origin
        		xyz="0 0 0"
       			rpy="0 0 0" />
      			<geometry>
        			<mesh
          			filename="package://fabribot_description/meshes/visual/base_link.stl" />
      			</geometry>
      			<material
        			name="abb_orange">
        			<color
          			rgba="1 0.43 0 1" />
      			</material>
    		</visual>
 			<collision>
				<geometry>
					<mesh filename="package://fabribot_description/meshes/collision/base_link.stl" />
				</geometry>
				<material name="yellow">
					<color rgba="0 1 1 1"/>
				</material>
			</collision>

		</link>
		<link name="${prefix}link_1">
			<visual>
      			<origin
        			xyz="0 0 0"
        			rpy="0 0 0" />
      			<geometry>
        			<mesh
          			filename="package://fabribot_description/meshes/visual/link_1.stl" />
      			</geometry>
      			<material name="abb_orange"/>
    		</visual>
			<collision>
      			<origin
        			xyz="0 0 0"
        			rpy="0 0 0" />
				<geometry>
					<mesh filename="package://fabribot_description/meshes/collision/link_1.stl" />
				</geometry>
				<material name="yellow"/>
			</collision>

		</link>
		<link name="${prefix}link_2">
		    <visual>
      			<origin
        			xyz="-0.175 0 -0.495"
        			rpy="0 0 0" />
      			<geometry>
        			<mesh
          			filename="package://fabribot_description/meshes/visual/link_2.stl" />
      			</geometry>
      			<material name="abb_orange"/>
    		</visual>
			<collision>
      			<origin
        			xyz="0 0 0"
        			rpy="0 0 0" />
				<geometry>
					<mesh filename="package://fabribot_description/meshes/collision/link_2.stl" />
				</geometry>
				<material name="yellow"/>
			</collision>

		</link>
		<link name="${prefix}link_3">
			<visual>
				<origin
					xyz="-0.175 0 -1.59"
					rpy="0 0 0" />
			  	<geometry>
					<mesh
				  	filename="package://fabribot_description/meshes/visual/link_3.stl" />
			  	</geometry>
			  	<material name="abb_orange"/>
			</visual>
			<collision>
      			<origin
        			xyz="0 0 0"
        			rpy="0 0 0" />
				<geometry>
					<mesh filename="package://fabribot_description/meshes/collision/link_3.stl" />
				</geometry>
				<material name="yellow"/>
			</collision>

		</link>
		<link name="${prefix}link_4">
			<visual>
				  <origin
					xyz="-0.507 0 -1.765"
					rpy="0 0 0" />
				  <geometry>
					<mesh
					  filename="package://fabribot_description/meshes/visual/link_4.stl" />
				  </geometry>
				  <material name="abb_orange"/>
			</visual>
			<collision>
      			<origin
        			xyz="0 0 0"
        			rpy="0 0 0" />
				<geometry>
					<mesh filename="package://fabribot_description/meshes/collision/link_4.stl" />
				</geometry>
				<material name="yellow"/>
			</collision>

		</link>
		<link name="${prefix}link_5">
			<visual>
				<origin
					xyz="-1.446 0 -1.765"
					rpy="0 0 0" />
				<geometry>
					<mesh
					  filename="package://fabribot_description/meshes/visual/link_5.stl" />
				</geometry>
				<material name="abb_orange"/>
			</visual>
			<collision>
      			<origin
        			xyz="0 0 0"
        			rpy="0 0 0" />
				<geometry>
					<mesh filename="package://fabribot_description/meshes/collision/link_5.stl" />
				</geometry>
				<material name="yellow"/>
			</collision>

		</link>
		<link name="${prefix}link_6">
			<visual>
				<origin
					xyz="-1.581 0 -1.765"
					rpy="0 0 0" />
				<geometry>
					<mesh
					  filename="package://fabribot_description/meshes/visual/link_6.stl" />
				</geometry>
				<material name="abb_orange"/>
			</visual>
			<collision>
      			<origin
        			xyz="0 0 0"
        			rpy="0 0 0" />
				<geometry>
					<mesh filename="package://fabribot_description/meshes/collision/link_6.stl" />
				</geometry>
				<material name="yellow"/>
			</collision>

		</link>
		<link name="${prefix}tool0"/>
		<!-- end of link list -->

		<!-- joint list -->


		<joint name="fixed" type="fixed"> <!-- ============================== fixing base link to world -->
		  <parent link="${prefix}world"/>
		  <child link="${prefix}base_link"/>
		</joint>


		<joint name="${prefix}joint_1" type="revolute"> <!-- ============================== joint 1 -->
			<origin
			  xyz="0 0 0"
			  rpy="0 0 0" />
			<parent
			  link="${prefix}base_link" />
			<child
			  link="${prefix}link_1" />
			<axis
			  xyz="0 0 1" />
			<limit
			  lower="-3.1416"
			  upper="3.1416"
			  effort="0"
			  velocity="2.618" />
			<calibration
			  rising="0"
			  falling="0" />
			<dynamics
			  damping="0"
			  friction="0" />
		</joint>
		<joint name="${prefix}joint_2" type="revolute"> <!-- ============================== joint 2 -->
			<origin
			  xyz="0.175 0 0.495" 
			  rpy="0 0 0" />
			<parent
			  link="${prefix}link_1" />
			<child
			  link="${prefix}link_2" />
			<axis
			  xyz="0 1 0" />
			<limit
			  lower="-1.7453"
			  upper="1.9199"
			  effort="0"
			  velocity="2.618" />
			<calibration
			  rising="0"
			  falling="0" />
			<dynamics
			  damping="0"
			  friction="0" />
  		</joint>
		<joint name="${prefix}joint_3" type="revolute"> <!-- ============================== joint 3 -->
			<origin
			  xyz="0 0 1.095"
			  rpy="0 0 0" />
			<parent
			  link="${prefix}link_2" />
			<child
			  link="${prefix}link_3" />
			<axis
			  xyz="0 1 0" />
			<limit
			  lower="-1.0472"
			  upper="1.1345"
			  effort="0"
			  velocity="2.618" />
			<calibration
			  rising="0"
			  falling="0" />
			<dynamics
			  damping="0"
			  friction="0" />
		</joint>
		<joint name="${prefix}joint_4" type="revolute"> <!-- ============================== joint 4 -->
			<origin
			  xyz="0.332 0 0.175"
			  rpy="0 0 0" />
			<parent
			  link="${prefix}link_3" />
			<child
			  link="${prefix}link_4" />
			<axis
			  xyz="1 0 0" />
			<limit
			  lower="-3.49"
			  upper="3.49"
			  effort="0"
			  velocity="6.2832" />
			<calibration
			  rising="0"
			  falling="0" />
			<dynamics
			  damping="0"
			  friction="0" />
		</joint>
		<joint name="${prefix}joint_5" type="revolute"> <!-- ============================== joint 5 -->
			<origin
			  xyz="0.939 0 0"
			  rpy="0 0 0" />
			<parent
			  link="${prefix}link_4" />
			<child
			  link="${prefix}link_5" />
			<axis
			  xyz="0 1 0" />
			<limit
			  lower="-2.0944"
			  upper="2.0944"
			  effort="0"
			  velocity="6.2832" />
			<calibration
			  rising="0"
			  falling="0" />
			<dynamics
			  damping="0"
			  friction="0" />
		</joint>
		<joint name="${prefix}joint_6" type="revolute"> <!-- ============================== joint 6 -->
			<origin
			  xyz="0.135 0 0"
			  rpy="0 0 0" />
			<parent
			  link="${prefix}link_5" />
			<child
			  link="${prefix}link_6" />
			<axis
			  xyz="1 0 0" />
			<limit
			  lower="-6.9813"
			  upper="6.9813"
			  effort="0"
			  velocity="7.854" />
			<calibration
			  rising="0"
			  falling="0" />
			<dynamics
			  damping="0"
			  friction="0" />
		</joint>
		<joint name="${prefix}joint_6-tool0" type="fixed"> <!-- ============================== tool 0 -->
			<parent link="${prefix}link_6"/>
			<child link="${prefix}tool0"/>
			<origin xyz="0 0 0" rpy="0 0 0"/>
		</joint>
		<!-- end of joint list -->
	</xacro:macro>
</robot>
